Workbook

Sheet AB Test Tracking
A1: A/B TEST TRACKING DASHBOARD - MayDo Fashion
A2: He thong theo doi A/B Test tu dong - Cap nhat Real-time khi nhap du lieu
A3: INPUT DATA (Nhap du lieu vao cac o nay) | Q3: AUTO-CALCULATED METRICS (Khong chinh sua)
A4: Test ID | B4: Test Name | C4: Date Started | D4: Date Ended | E4: Variant A (Video/Content) | F4: Variant B (Video/Content) | G4: Budget A (VND) | H4: Budget B (VND) | I4: Impressions A | J4: Impressions B | K4: Clicks A | L4: Clicks B | M4: Conversions A | N4: Conversions B | O4: Revenue A (VND) | P4: Revenue B (VND) | Q4: CTR A (%) | R4: CTR B (%) | S4: CPM A (VND) | T4: CPM B (VND) | U4: CPC A (VND) | V4: CPC B (VND) | W4: CVR A (%) | X4: CVR B (%) | Y4: ROAS A | Z4: ROAS B | AA4: Winner (Auto) | AB4: Confidence Level
A5: AB001 | B5: Before/After Video vs Static Image | C5: 2026-04-01 | D5: 2026-04-07 | E5: Video Before/After (60s) - Set vay trang | F5: Static Image - Lookbook Set vay trang | G5: 500000 | H5: 500000 | I5: 25000 | J5: 22000 | K5: 750 | L5: 440 | M5: 15 | N5: 8 | O5: 9750000 | P5: 5200000 | Q5: =IF(I5=0,"",K5/I5*100) | R5: =IF(J5=0,"",L5/J5*100) | S5: =IF(I5=0,"",G5/I5*1000) | T5: =IF(J5=0,"",H5/J5*1000) | U5: =IF(K5=0,"",G5/K5) | V5: =IF(L5=0,"",H5/L5) | W5: =IF(K5=0,"",M5/K5*100) | X5: =IF(L5=0,"",N5/L5*100) | Y5: =IF(G5=0,"",O5/G5) | Z5: =IF(H5=0,"",P5/H5) | AA5: =IF(OR(Y5="",Z5=""),"Pending",IF(Y5>Z5,"VARIANT A WINS","VARIANT B WINS")) | AB5: =IF(OR(Y5="",Z5=""),"N/A",IF(ABS(Y5-Z5)/MAX(Y5,Z5)>0.3,"High (>30%)",IF(ABS(Y5-Z5)/MAX(Y5,Z5)>0.15,"Medium (15-30%)","Low (<15%)")))
A6: AB002 | B6: Customer Testimonial vs Process Video | C6: 2026-04-08 | D6: 2026-04-14 | E6: Video Feedback KH Nguyen Thi H. | F6: Video Quy trinh may do (45s) | G6: 600000 | H6: 600000 | I6: 31000 | J6: 28500 | K6: 930 | L6: 855 | M6: 22 | N6: 14 | O6: 15400000 | P6: 9800000 | Q6: =IF(I6=0,"",K6/I6*100) | R6: =IF(J6=0,"",L6/J6*100) | S6: =IF(I6=0,"",G6/I6*1000) | T6: =IF(J6=0,"",H6/J6*1000) | U6: =IF(K6=0,"",G6/K6) | V6: =IF(L6=0,"",H6/L6) | W6: =IF(K6=0,"",M6/K6*100) | X6: =IF(L6=0,"",N6/L6*100) | Y6: =IF(G6=0,"",O6/G6) | Z6: =IF(H6=0,"",P6/H6) | AA6: =IF(OR(Y6="",Z6=""),"Pending",IF(Y6>Z6,"VARIANT A WINS","VARIANT B WINS")) | AB6: =IF(OR(Y6="",Z6=""),"N/A",IF(ABS(Y6-Z6)/MAX(Y6,Z6)>0.3,"High (>30%)",IF(ABS(Y6-Z6)/MAX(Y6,Z6)>0.15,"Medium (15-30%)","Low (<15%)")))
A7: AB003 | B7: TOF Hook A vs Hook B | C7: 2026-04-15 | D7: 2026-04-21 | E7: Hook: "Ban da bao gio mac ao khong vua?" | F7: Hook: "3 ly do do may tot hon san" | G7: 400000 | H7: 400000 | I7: 18500 | J7: 21000 | K7: 555 | L7: 735 | M7: 9 | N7: 18 | O7: 6300000 | P7: 12600000 | Q7: =IF(I7=0,"",K7/I7*100) | R7: =IF(J7=0,"",L7/J7*100) | S7: =IF(I7=0,"",G7/I7*1000) | T7: =IF(J7=0,"",H7/J7*1000) | U7: =IF(K7=0,"",G7/K7) | V7: =IF(L7=0,"",H7/L7) | W7: =IF(K7=0,"",M7/K7*100) | X7: =IF(L7=0,"",N7/L7*100) | Y7: =IF(G7=0,"",O7/G7) | Z7: =IF(H7=0,"",P7/H7) | AA7: =IF(OR(Y7="",Z7=""),"Pending",IF(Y7>Z7,"VARIANT A WINS","VARIANT B WINS")) | AB7: =IF(OR(Y7="",Z7=""),"N/A",IF(ABS(Y7-Z7)/MAX(Y7,Z7)>0.3,"High (>30%)",IF(ABS(Y7-Z7)/MAX(Y7,Z7)>0.15,"Medium (15-30%)","Low (<15%)")))
A8: AB004 | B8: MOF Retarget - Video 75% vs Engaged | C8: 2026-04-22 | D8: 2026-04-28 | E8: Audience: Watched >75% TOF video | F8: Audience: Engaged with FB profile 30d | G8: 300000 | H8: 300000 | I8: 8200 | J8: 11500 | K8: 410 | L8: 460 | M8: 12 | N8: 11 | O8: 8400000 | P8: 7700000 | Q8: =IF(I8=0,"",K8/I8*100) | R8: =IF(J8=0,"",L8/J8*100) | S8: =IF(I8=0,"",G8/I8*1000) | T8: =IF(J8=0,"",H8/J8*1000) | U8: =IF(K8=0,"",G8/K8) | V8: =IF(L8=0,"",H8/L8) | W8: =IF(K8=0,"",M8/K8*100) | X8: =IF(L8=0,"",N8/L8*100) | Y8: =IF(G8=0,"",O8/G8) | Z8: =IF(H8=0,"",P8/H8) | AA8: =IF(OR(Y8="",Z8=""),"Pending",IF(Y8>Z8,"VARIANT A WINS","VARIANT B WINS")) | AB8: =IF(OR(Y8="",Z8=""),"N/A",IF(ABS(Y8-Z8)/MAX(Y8,Z8)>0.3,"High (>30%)",IF(ABS(Y8-Z8)/MAX(Y8,Z8)>0.15,"Medium (15-30%)","Low (<15%)")))
A9: AB005 | B9: BOF CTA - Nhan tin ngay vs Xem BST | C9: 2026-05-01 | D9: 2026-05-03 | E9: CTA: Nhan tin ngay + Offer 10% | F9: CTA: Xem bo suu tap (Catalog) | G9: 250000 | H9: 250000 | I9: 9500 | J9: 9200 | K9: 285 | L9: 184 | M9: 9 | N9: 5 | O9: 6750000 | P9: 3750000 | Q9: =IF(I9=0,"",K9/I9*100) | R9: =IF(J9=0,"",L9/J9*100) | S9: =IF(I9=0,"",G9/I9*1000) | T9: =IF(J9=0,"",H9/J9*1000) | U9: =IF(K9=0,"",G9/K9) | V9: =IF(L9=0,"",H9/L9) | W9: =IF(K9=0,"",M9/K9*100) | X9: =IF(L9=0,"",N9/L9*100) | Y9: =IF(G9=0,"",O9/G9) | Z9: =IF(H9=0,"",P9/H9) | AA9: =IF(OR(Y9="",Z9=""),"Pending",IF(Y9>Z9,"VARIANT A WINS","VARIANT B WINS")) | AB9: =IF(OR(Y9="",Z9=""),"N/A",IF(ABS(Y9-Z9)/MAX(Y9,Z9)>0.3,"High (>30%)",IF(ABS(Y9-Z9)/MAX(Y9,Z9)>0.15,"Medium (15-30%)","Low (<15%)")))
A11: HUONG DAN: Nhap du lieu vao cot A-P. Cot Q-AB tu dong tinh toan. Winner = ROAS cao hon. Confidence = % chenh lech ROAS.
A12: LEGEND / CHU THICH | C12: High Confidence: ROAS diff >30% | D12: Medium Confidence: ROAS diff 15-30% | E12: Low Confidence: ROAS diff <15% | F12: Auto-calc columns (orange)

Sheet Meta Retargeting Guide
A1: META ADS RETARGETING SETUP GUIDE - MayDo Fashion Funnel
A2: Huong dan tao audiences MOF & BOF trong Meta Ads Manager - TOF -> MOF -> BOF Funnel
A3: FUNNEL OVERVIEW: TOF -> MOF -> BOF
B4: Stage | C4: Muc tieu | D4: Budget % | E4: Audience Target | F4: Content Type
B5: TOF - Top of Funnel | C5: Awareness - Tiep can nguoi moi | D5: 50% tong ngan sach | E5: Lookalike 1-3%, Interest targeting | F5: Before/After Video, Process Video
B6: MOF - Mid of Funnel | C6: Consideration - Nuoi duong intent | D6: 30% tong ngan sach | E6: Xem >50% TOF video, Profile visits | F6: Testimonial, Detail Product, FAQ
B7: BOF - Bottom of Funnel | C7: Conversion - Chuyen doi mua hang | D7: 20% tong ngan sach | E7: Xem >75% MOF, Website visit, DM | F7: Offer, CTA manh, Social Proof
A9: MOF AUDIENCE SETUP - Mid of Funnel Retargeting
A10: BUOC 1: Tao Custom Audience cho MOF
B11: Buoc | C11: Mo ta chi tiet | D11: Cai dat cu the | E11: Ghi chu
B12: Truy cap | C12: Meta Ads Manager -> Audiences -> Create Audience -> Custom Audience -> Video
B13: Dieu kien 1: Video View 50-75% | C13: People who watched 50% to 75% of your video - Chon tat ca video TOF (Before/After, Process) - Lookback window: 30 ngay | D13: Vao: Ads Manager > Audiences > Create > Custom Audience > Video > "People who watched at least 50% of your video" | E13: Bat buoc phai co video TOF chay truoc
B14: Dieu kien 2: Profile Visits | C14: People who visited your business profile - Facebook Page: All visits - Instagram Profile: All visits - Lookback: 60 ngay | D14: Custom Audience > Instagram Account > People who visited your profile > Last 60 days | E14: Ket hop OR logic voi dieu kien 1
B15: Dieu kien 3: Post Engagement | C15: People who engaged with any post or ad - Bao gom: Like, Comment, Share, Save, Click link - Lookback: 30 ngay | D15: Custom Audience > Facebook Page > People who engaged with any post/ad > Last 30 days | E15: Engage = hanh dong tich cuc, quality cao
B16: Combine Logic | C16: Su dung ANY OF (OR logic) de ket hop 3 dieu kien -> Audience size muc tieu: 10,000 - 100,000 nguoi | D16: Kiem tra audience size truoc khi luu Neu < 5,000: Mo rong lookback window | E16: Audience qua nho = khong du data de optimize
B17: EXCLUSIONS (Bat buoc) | C17: LOAI TRU cac doi tuong: 1. BOF Audience (khach gan mua) 2. Khach hang cu da mua (upload list SDD/email) 3. Negative engagement (hide ad, report) | D17: Them Exclusion trong Custom Audience Upload danh sach CSV so dien thoai khach cu Format: +84xxxxxxxxx | E17: Exclusion giup giam chi phi, tang relevance
B18: Warm-up Period | C18: Phase 1 (Ngay 1-3): Learning phase - KHONG TAT ad, KHONG chinh sua - Can toi thieu 50 conversions/tuan Phase 2 (Ngay 4-7): Bat dau optimize | D18: Budget toi thieu de thoat Learning Phase: CPA muc tieu x 50 events / 7 ngay Vi du: CPA = 50K x 50 / 7 = ~357K/ngay | E18: Kien nhan voi learning phase!
B19: Refresh Rate | C19: Refresh audience moi 30 ngay: - Cap nhat lookback period - Them video TOF moi vao pool - Review exclusion list | D19: Dat lich nhan viec reminder trong Google Calendar (moi 30 ngay mot lan) | E19: Tranh audience fatigue sau 30 ngay
A21: BUOC 2: Cai dat Ad Set cho MOF Campaign
B22: Cai dat | C22: Huong dan chi tiet | D22: Best Practice | E22: KPI Muc tieu
B23: Campaign Objective | C23: Traffic hoac Engagement (neu funnel chin: dung Conversions) | D23: Bat dau voi Traffic, switch sang Conversions khi co data | E23: CTR > 2.5%, CPM < 80K
B24: Audience Setting | C24: MOF Custom Audience da tao o Buoc 1 Bat Advantage Audience neu size < 5,000 | D24: KHONG dung Interest targeting cho MOF (da co custom audience) | E24: Audience size: 10K-100K
B25: Placement | C25: Manual Placements: - Facebook Feed - Instagram Feed - Reels Tat Audience Network | D25: Audience Network thuong co CTR cao nhung quality kem | E25: Placement uu tien: Reels > Feed
B26: Budget & Bidding | C26: 30% tong ngan sach ngay Vi du: Budget 1M/ngay -> MOF: 300K Dung Lowest Cost bidding | D26: Budget toi thieu: 150K/ngay/ad set Scale 20% moi 3-5 ngay neu tot | E26: ROAS > 3x, CPM < 80K
B27: Schedule & Delivery | C27: Chay lien tuc 7 ngay Khong gioi han gio chay Khong dung Accelerated delivery | D27: Review ket qua sau 3 ngay dau tien Khong can chinh sua trong learning phase | E27: Frequency: 3-5 lan/nguoi/tuan
B28: Ad Creative | C28: Su dung Testimonial videos, Detail Product Co CTA ro rang: "Nhan tin de tu van" | D28: Video dai 30-60s, co phu de (caption) Thumbnail dep, ro mat nguoi mac | E28: Video View Rate > 50%
A30: BOF AUDIENCE SETUP - Bottom of Funnel Retargeting
A31: BUOC 1: Tao Custom Audience cho BOF
B32: Buoc | C32: Mo ta chi tiet | D32: Cai dat cu the | E32: Ghi chu quan trong
B33: Dieu kien 1: Video >75% MOF (QUAN TRONG NHAT) | C33: People who watched 75% or more of MOF video - Day la tin hieu manh nhat - Lookback: 30 ngay | D33: Custom Audience > Video > People who watched at least 75% > Chon tat ca MOF videos | E33: MUST HAVE - Khong co dieu kien nay BOF rat yeu
B34: Dieu kien 2: Website Visits | C34: People who visited your website - Can cai dat Meta Pixel tren website - URL: Domain.com/collections hoac /products - Lookback: 60 ngay | D34: Custom Audience > Website > All website visitors > Or: specific product/collection pages YEU CAU: Meta Pixel phai duoc cai dat! | E34: Pixel: Ads Manager > Events Manager > Add Pixel
B35: Dieu kien 3: Profile 30+ seconds | C35: People who spent 30+ seconds on your profile - Instagram Business Profile - Lookback: 30 ngay - Day la signal manh, cho thay interest cao | D35: Custom Audience > Instagram Account > People who spent 30+ seconds on your profile > Last 30 days | E35: Chi kha dung cho Instagram Business
B36: Dieu kien 4: Messaged Your Business (QUAN TRONG) | C36: People who sent a message to your page/profile - Facebook Messenger - Instagram Direct Message - Lookback: 30-60 ngay | D36: Custom Audience > Facebook Page > People who sent a message > Last 60 days Va: Instagram > People who sent a DM | E36: Nhom nay da co intent ro rang - uu tien cao!
B37: Combine Logic | C37: ANY OF (OR logic) cho 4 dieu kien tren Audience size muc tieu: 2,000 - 20,000 | D37: Kiem tra overlap giua cac audience Neu overlap > 30%: can xem xet loai bo 1 dieu kien | E37: Audience qua lon (>50K) = giam hieu qua BOF
B38: EXCLUSIONS (Bat buoc) | C38: LOAI TRU TUYET DOI: 1. Khach da chot don (upload list) 2. Khach huy don 3. Audience nen MOF (de tranh chong cheo) 4. Negative users | D38: Upload CSV danh sach so dien thoai khach cu moi tuan Format: +84xxxxxxxxx, 1 so/dong Toi da: 15 trieu records/list | E38: Cac phep tinh quang cao se sai neu khong exclude!
B39: Lookalike Opportunity | C39: Sau khi co du lieu BOF: -> Tao Lookalike 1% tu BOF audience -> Su dung Lookalike nay cho TOF campaign -> Day la "anh em" cua khach hang tot nhat | D39: Audience > Create Audience > Lookalike > Source: BOF Custom Audience > Audience size: 1-2% | E39: Can it nhat 1,000 nguoi trong BOF audience
A41: BUOC 2: Best Practices cho BOF Campaign
B42: Best Practice | C42: Chi tiet thuc hien | D42: Vi du / Mau noi dung | E42: KPI muc tieu
B43: Creative Strategy | C43: Su dung Social Proof manh: - Anh review 5 sao, comments thuc - Video truoc-sau cua nhieu khach - Trust badges: "500+ khach hang tin tuong" | D43: "Chi Lan - Sai Gon: May xong dep hon hinh!" "Anh chup khong dung chat luong san pham" | E43: CVR > 5%, CTR > 3.5%
B44: Offer & CTA | C44: Dua ra offer co thoi han: - Giam 10-15% cho lan dat may dau - "Chi con 3 suat tuan nay" - Free shipping / Mien phi do | D44: "Nhan tin ngay - Giam 10% don may dau" "Offer chi con gia tri den het tuan" | E44: Close Rate inbox > 30%
...

Sheet Dashboard Tong Hop
A1: DASHBOARD TONG HOP - MayDo Fashion Analytics
A2: =TEXT(TODAY(),"YYYY-MM-DD")&" - Tu dong cap nhat tu sheet Data Input Template"
A3: OVERVIEW KPIs - TONG QUAN THANG NAY
B4: TONG DON HANG | D4: TONG DOANH THU (d) | F4: TONG CHI PHI ADS (d) | H4: ROAS TONG | J4: TY LE CHUYEN DOI | L4: TOTAL MSG
B5: ='Data Input Template'!F2 | D5: ='Data Input Template'!G2 | F5: ='Data Input Template'!H2 | H5: =IF('Data Input Template'!H2=0,"N/A",'Data Input Template'!G2/'Data Input Template'!H2) | J5: =IF('Data Input Template'!B2=0,"N/A",'Data Input Template'!F2/'Data Input Template'!B2*100) | L5: ='Data Input Template'!B2
B6: =IF(OR('Data Input Template'!F2=0,'Data Input Template'!F3=0),"-- No prev week data",IF('Data Input Template'!F2>'Data Input Template'!F3,"UP "&TEXT(('Data Input Template'!F2-'Data Input Template'!F3)/'Data Input Template'!F3*100,"0.0")&"% vs W-1","DOWN "&TEXT(ABS(('Data Input Template'!F2-'Data Input Template'!F3)/'Data Input Template'!F3*100),"0.0")&"% vs W-1")) | D6: =IF(OR('Data Input Template'!G2=0,'Data Input Template'!G3=0),"-- No prev week data",IF('Data Input Template'!G2>'Data Input Template'!G3,"UP "&TEXT(('Data Input Template'!G2-'Data Input Template'!G3)/'Data Input Template'!G3*100,"0.0")&"% WoW","DOWN "&TEXT(ABS(('Data Input Template'!G2-'Data Input Template'!G3)/'Data Input Template'!G3*100),"0.0")&"% WoW")) | F6: =IF(OR('Data Input Template'!H2=0,'Data Input Template'!H3=0),"-- No prev week data",IF('Data Input Template'!H2<'Data Input Template'!H3,"GIAM "&TEXT(ABS(('Data Input Template'!H2-'Data Input Template'!H3)/'Data Input Template'!H3*100),"0.0")&"% (tot)","TANG "&TEXT(('Data Input Template'!H2-'Data Input Template'!H3)/'Data Input Template'!H3*100,"0.0")&"% (xem lai)")) | H6: "Cap nhat moi tuan" | J6: "Cap nhat moi tuan" | L6: "Cap nhat moi tuan"
A8: INBOX PERFORMANCE - PHAN TICH TY LE CHOT DON
B9: Customer Type | C9: Msg Received | D9: Replied | E9: Quoted | F9: Ordered | G9: Response Rate | H9: Quote Rate | I9: Close Rate | J9: AOV (d) | K9: Revenue | L9: Target Close% | M9: Status
B10: Hot (>75% MOF) | C10: 0 | D10: 0 | E10: 0 | F10: 0 | G10: =IF(C10=0,"",D10/C10*100) | H10: =IF(D10=0,"",E10/D10*100) | I10: =IF(C10=0,"",F10/C10*100) | J10: 0 | K10: =IF(OR(F10=0,J10=0),"",F10*J10) | L10: 65 | M10: =IF(I10="","No data",IF(VALUE(SUBSTITUTE(I10,"%",""))>=L10,"On Track","Below Target"))
B11: Warm (50-75%) | C11: 0 | D11: 0 | E11: 0 | F11: 0 | G11: =IF(C11=0,"",D11/C11*100) | H11: =IF(D11=0,"",E11/D11*100) | I11: =IF(C11=0,"",F11/C11*100) | J11: 0 | K11: =IF(OR(F11=0,J11=0),"",F11*J11) | L11: 45 | M11: =IF(I11="","No data",IF(VALUE(SUBSTITUTE(I11,"%",""))>=L11,"On Track","Below Target"))
B12: Cold (<50%) | C12: 0 | D12: 0 | E12: 0 | F12: 0 | G12: =IF(C12=0,"",D12/C12*100) | H12: =IF(D12=0,"",E12/D12*100) | I12: =IF(C12=0,"",F12/C12*100) | J12: 0 | K12: =IF(OR(F12=0,J12=0),"",F12*J12) | L12: 20 | M12: =IF(I12="","No data",IF(VALUE(SUBSTITUTE(I12,"%",""))>=L12,"On Track","Below Target"))
B13: Bargain Hunters | C13: 0 | D13: 0 | E13: 0 | F13: 0 | G13: =IF(C13=0,"",D13/C13*100) | H13: =IF(D13=0,"",E13/D13*100) | I13: =IF(C13=0,"",F13/C13*100) | J13: 0 | K13: =IF(OR(F13=0,J13=0),"",F13*J13) | L13: 25 | M13: =IF(I13="","No data",IF(VALUE(SUBSTITUTE(I13,"%",""))>=L13,"On Track","Below Target"))
A16: ADS PERFORMANCE - TOF / MOF / BOF BREAKDOWN
B17: Funnel Stage | C17: Budget Plan | D17: Actual Spend | E17: Impressions | F17: Clicks | G17: Conversions | H17: CPM (d) | I17: CTR (%) | J17: CPC (d) | K17: Revenue (d) | L17: ROAS | M17: Budget vs Plan
B18: TOF - Top of Funnel (50%) | C18: 0 | D18: 0 | E18: 0 | F18: 0 | G18: 0 | H18: =IF(OR(C18=0,D18=0),"",C18/D18*1000) | I18: =IF(OR(E18=0,D18=0),"",E18/D18*100) | J18: =IF(OR(E18=0,C18=0),"",C18/E18) | K18: 0 | L18: =IF(OR(C18=0,K18=0),"",K18/C18) | M18: =IF(OR(B18=0,C18=0),"",C18/B18*100)
B19: MOF - Mid of Funnel (30%) | C19: 0 | D19: 0 | E19: 0 | F19: 0 | G19: 0 | H19: =IF(OR(C19=0,D19=0),"",C19/D19*1000) | I19: =IF(OR(E19=0,D19=0),"",E19/D19*100) | J19: =IF(OR(E19=0,C19=0),"",C19/E19) | K19: 0 | L19: =IF(OR(C19=0,K19=0),"",K19/C19) | M19: =IF(OR(B19=0,C19=0),"",C19/B19*100)
B20: BOF - Bottom of Funnel (20%) | C20: 0 | D20: 0 | E20: 0 | F20: 0 | G20: 0 | H20: =IF(OR(C20=0,D20=0),"",C20/D20*1000) | I20: =IF(OR(E20=0,D20=0),"",E20/D20*100) | J20: =IF(OR(E20=0,C20=0),"",C20/E20) | K20: 0 | L20: =IF(OR(C20=0,K20=0),"",K20/C20) | M20: =IF(OR(B20=0,C20=0),"",C20/B20*100)
B21: TOTAL | C21: =SUM(C18:C20) | D21: =SUM(D18:D20) | E21: =SUM(E18:E20) | F21: =SUM(F18:F20) | G21: =SUM(G18:G20) | H21: =IF(E21=0,"",D21/E21*1000) | I21: =IF(OR(F21=0,E21=0),"",F21/E21*100) | J21: =IF(OR(F21=0,D21=0),"",D21/F21) | K21: =SUM(K18:K20) | L21: =IF(OR(D21=0,K21=0),"",K21/D21)
A23: TOP CONTENT PERFORMANCE - BAI DANG HIEU QUA NHAT
B24: # | C24: Post/Video Name | D24: Content Type | E24: Platform | F24: Views | G24: Reach | H24: Saves | I24: Shares | J24: Comments | K24: Engagement Rate | L24: Save Rate | M24: Perf Score
B25: 1 | C25: Before/After Vay trang KH Ha | D25: BEFORE-AFTER | E25: Reels | F25: 45200 | G25: 38000 | H25: 1240 | I25: 380 | J25: 95 | K25: =IF(G25=0,"",(H25+I25+J25)/G25*100) | L25: =IF(F25=0,"",H25/F25*100) | M25: =ROUND((F25*0.3+H25*0.4+I25*0.3)/1000,1)
B26: 2 | C26: Quy trinh do dac 60s | D26: PROCESS | E26: Reels | F26: 32100 | G26: 27500 | H26: 890 | I26: 220 | J26: 67 | K26: =IF(G26=0,"",(H26+I26+J26)/G26*100) | L26: =IF(F26=0,"",H26/F26*100) | M26: =ROUND((F26*0.3+H26*0.4+I26*0.3)/1000,1)
B27: 3 | C27: Pinterest to Localize Set Thu Dong | D27: PINTEREST-LOCAL | E27: Carousel | F27: 28700 | G27: 24000 | H27: 1560 | I27: 180 | J27: 43 | K27: =IF(G27=0,"",(H27+I27+J27)/G27*100) | L27: =IF(F27=0,"",H27/F27*100) | M27: =ROUND((F27*0.3+H27*0.4+I27*0.3)/1000,1)
B28: 4 | C28: Customer Review KH Nguyen H. | D28: TESTIMONIAL | E28: Video | F28: 21300 | G28: 19000 | H28: 670 | I28: 145 | J28: 112 | K28: =IF(G28=0,"",(H28+I28+J28)/G28*100) | L28: =IF(F28=0,"",H28/F28*100) | M28: =ROUND((F28*0.3+H28*0.4+I28*0.3)/1000,1)
B29: 5 | C29: Problem: Ao khong vua vai? | D29: PROBLEM-SOLUTION | E29: Reels | F29: 19800 | G29: 17200 | H29: 520 | I29: 130 | J29: 88 | K29: =IF(G29=0,"",(H29+I29+J29)/G29*100) | L29: =IF(F29=0,"",H29/F29*100) | M29: =ROUND((F29*0.3+H29*0.4+I29*0.3)/1000,1)
A32: AI AGENT RECOMMENDATIONS - DE XUAT TU DONG
B33: Priority | C33: Category | D33: Recommendation | E33: Based on Metric | F33: Action Required | G33: Target Impact
B34: HIGH | C34: Budget | D34: Tang ngan sach BOF khi ROAS BOF > 5x - nhom nay gan mua nhat | E34: ROAS BOF > 5x | F34: Chuyen 10% budget TOF -> BOF | G34: +15-25% Revenue
B35: HIGH | C35: Content | D35: San xuat them Before/After videos - Save Rate cao nhat trong tat ca loai content | E35: Save Rate > 3% | F35: Len lich 2 video B/A moi tuan | G35: Giam CPM 20%
B36: MEDIUM | C36: Inbox | D36: Cold leads can nurture sequence 5-7 ngay truoc khi push close | E36: Close Rate Cold < 10% | F36: Setup automation sequence | G36: +10% Close Rate
B37: MEDIUM | C37: A/B Test | D37: Luon chay it nhat 1 A/B test - khong bao gio de "status quo" | E37: AB Test Cadence | F37: Khoi dong test moi moi 7 ngay | G37: Toi uu lien tuc
B38: LOW | C38: Audience | D38: Kiem tra frequency BOF audience - neu > 5 thi refresh creative | E38: Ad Frequency > 5 | F38: Cap nhat creative set BOF | G38: Giam ad fatigue
B39: LOW | C39: MOF Funnel | D39: Mo rong MOF audience bang cach them 90-day lookback | E39: MOF Audience Size | F39: Tao MOF audience 90 ngay | G39: +20% MOF reach

Sheet Data Input Template
A1: DATA INPUT TEMPLATE - NHAP DU LIEU HANG TUAN
A2: HUONG DAN: O mau xanh la = nhap du lieu. O mau xam = tu dong tinh. Dashboard Tong Hop se tu dong cap nhat.
A3: SECTION A: TONG QUAN THEO TUAN (Nhap 1 lan/tuan)
B4: Tuan / Period | C4: Total Messages | D4: Replied | E4: Quoted | F4: Ordered | G4: Total Orders | H4: Total Revenue (d) | I4: Total Ad Spend (d) | J4: Date Start | K4: Date End | L4: ROAS (Auto) | M4: Notes
B5: Tuan 1 | C5: 0 | D5: 0 | E5: 0 | F5: 0 | G5: 0 | H5: 0 | I5: 0 | K5: =IF(OR(H5=0,I5=0),"",H5/I5)
B6: Tuan 2 | C6: 0 | D6: 0 | E6: 0 | F6: 0 | G6: 0 | H6: 0 | I6: 0 | K6: =IF(OR(H6=0,I6=0),"",H6/I6)
B7: Tuan 3 | C7: 0 | D7: 0 | E7: 0 | F7: 0 | G7: 0 | H7: 0 | I7: 0 | K7: =IF(OR(H7=0,I7=0),"",H7/I7)
B8: Tuan 4 | C8: 0 | D8: 0 | E8: 0 | F8: 0 | G8: 0 | H8: 0 | I8: 0 | K8: =IF(OR(H8=0,I8=0),"",H8/I8)
A10: SECTION B: INBOX BREAKDOWN BY CUSTOMER TYPE (Nhap theo tuan)
B11: Customer Type | C11: Msg Received | D11: Replied | E11: Quoted | F11: Ordered | G11: Cancelled | H11: Close Rate (Auto) | I11: AOV (d) | J11: Revenue (Auto) | K11: Notes
B12: Hot (>75% MOF) | C12: 0 | D12: 0 | E12: 0 | F12: 0 | G12: 0 | H12: =IF(C12=0,"",F12/C12*100) | I12: 0 | J12: =IF(OR(F12=0,I12=0),"",F12*I12)
B13: Warm (50-75%) | C13: 0 | D13: 0 | E13: 0 | F13: 0 | G13: 0 | H13: =IF(C13=0,"",F13/C13*100) | I13: 0 | J13: =IF(OR(F13=0,I13=0),"",F13*I13)
B14: Cold (<50%) | C14: 0 | D14: 0 | E14: 0 | F14: 0 | G14: 0 | H14: =IF(C14=0,"",F14/C14*100) | I14: 0 | J14: =IF(OR(F14=0,I14=0),"",F14*I14)
B15: Bargain Hunters | C15: 0 | D15: 0 | E15: 0 | F15: 0 | G15: 0 | H15: =IF(C15=0,"",F15/C15*100) | I15: 0 | J15: =IF(OR(F15=0,I15=0),"",F15*I15)
A17: SECTION C: ADS PERFORMANCE - TOF / MOF / BOF (Copy tu Meta Ads Manager)
B18: HUONG DAN COPY TU META: Ads Manager -> Campaigns -> Performance & Clicks -> Copy bang so lieu -> Paste vao cac o duoi day
B19: Funnel Stage | C19: Budget Plan (d) | D19: Actual Spend (d) | E19: Impressions | F19: Clicks | G19: Conversions (Msg) | H19: CPM (Auto) | I19: CTR (Auto) | J19: CPC (Auto) | K19: Revenue (d) | L19: ROAS (Auto) | M19: Video View%
B20: TOF - Top of Funnel | C20: 0 | D20: 0 | E20: 0 | F20: 0 | G20: 0 | H20: 0 | I20: =IF(OR(C20=0,D20=0),"",C20/D20*1000) | J20: =IF(OR(E20=0,D20=0),"",E20/D20*100) | K20: =IF(OR(E20=0,C20=0),"",C20/E20) | L20: 0 | M20: =IF(OR(C20=0,L20=0),"",L20/C20) | N20: 0
B21: MOF - Mid of Funnel | C21: 0 | D21: 0 | E21: 0 | F21: 0 | G21: 0 | H21: 0 | I21: =IF(OR(C21=0,D21=0),"",C21/D21*1000) | J21: =IF(OR(E21=0,D21=0),"",E21/D21*100) | K21: =IF(OR(E21=0,C21=0),"",C21/E21) | L21: 0 | M21: =IF(OR(C21=0,L21=0),"",L21/C21) | N21: 0
B22: BOF - Bottom of Funnel | C22: 0 | D22: 0 | E22: 0 | F22: 0 | G22: 0 | H22: 0 | I22: =IF(OR(C22=0,D22=0),"",C22/D22*1000) | J22: =IF(OR(E22=0,D22=0),"",E22/D22*100) | K22: =IF(OR(E22=0,C22=0),"",C22/E22) | L22: 0 | M22: =IF(OR(C22=0,L22=0),"",L22/C22) | N22: 0
A24: SECTION D: CONTENT TRACKING - NHAP KET QUA BAI DANG (Top 10)
B25: # | C25: Post/Video Title | D25: Content Pillar | E25: Platform | F25: Post Date | G25: Views | H25: Reach | I25: Saves | J25: Shares | K25: Comments | L25: Likes | M25: Engagement Rate (Auto)
B26: 1 | N26: =IF(OR(G26=0,G26=""),"",(H26+I26+J26+K26)/G26*100)
B27: 2 | N27: =IF(OR(G27=0,G27=""),"",(H27+I27+J27+K27)/G27*100)
B28: 3 | N28: =IF(OR(G28=0,G28=""),"",(H28+I28+J28+K28)/G28*100)
B29: 4 | N29: =IF(OR(G29=0,G29=""),"",(H29+I29+J29+K29)/G29*100)
B30: 5 | N30: =IF(OR(G30=0,G30=""),"",(H30+I30+J30+K30)/G30*100)
B31: 6 | N31: =IF(OR(G31=0,G31=""),"",(H31+I31+J31+K31)/G31*100)
B32: 7 | N32: =IF(OR(G32=0,G32=""),"",(H32+I32+J32+K32)/G32*100)
B33: 8 | N33: =IF(OR(G33=0,G33=""),"",(H33+I33+J33+K33)/G33*100)
B34: 9 | N34: =IF(OR(G34=0,G34=""),"",(H34+I34+J34+K34)/G34*100)
B35: 10 | N35: =IF(OR(G35=0,G35=""),"",(H35+I35+J35+K35)/G35*100)
A37: COLOR GUIDE - Huong dan mau sac
B38: O XANH LA: O nhap lieu - Ban PHAI nhap du lieu vao day
B39: O XAM: O tu dong tinh - KHONG chinh sua
B40: O VANG: Chu thich / ghi chu quan trong
B41: O DO: Canh bao hoac KPI quan trong
B42: O XANH DUONG: Header va nhan phan loai
